ERROR:django.request:Internal Server Error: /api/v1/users/
Traceback (most recent call last):
  File "c:\Python27\lib\site-packages\django\core\handlers\base.py", line 98, in get_response
    resolver_match = resolver.resolve(request.path_info)
  File "c:\Python27\lib\site-packages\django\core\urlresolvers.py", line 338, in resolve
    for pattern in self.url_patterns:
  File "c:\Python27\lib\site-packages\django\core\urlresolvers.py", line 367, in url_patterns
    patterns = getattr(self.urlconf_module, "urlpatterns", self.urlconf_module)
  File "c:\Python27\lib\site-packages\django\core\urlresolvers.py", line 361, in urlconf_module
    self._urlconf_module = import_module(self.urlconf_name)
  File "c:\Python27\lib\importlib\__init__.py", line 37, in import_module
    __import__(name)
  File "c:\Users\Junior\tappsi_test\tappsi_test\urls.py", line 2, in <module>
    from tappsi_api.views import UserViewSet, RideViewSet, AvailableView
  File "c:\Users\Junior\tappsi_test\tappsi_api\views.py", line 77
    taxi_drivers=Ride.objects.exclude(Q(user = invite.host) | Q(user = User(id =  id_guest) taxi_drive__in=user_ids, active=0).values_list('id', flat=True)
                                                                                                         ^
SyntaxError: invalid syntax
ERROR:django.request:Internal Server Error: /api/v1/users/
Traceback (most recent call last):
  File "c:\Python27\lib\site-packages\django\core\handlers\base.py", line 98, in get_response
    resolver_match = resolver.resolve(request.path_info)
  File "c:\Python27\lib\site-packages\django\core\urlresolvers.py", line 338, in resolve
    for pattern in self.url_patterns:
  File "c:\Python27\lib\site-packages\django\core\urlresolvers.py", line 367, in url_patterns
    patterns = getattr(self.urlconf_module, "urlpatterns", self.urlconf_module)
  File "c:\Python27\lib\site-packages\django\core\urlresolvers.py", line 361, in urlconf_module
    self._urlconf_module = import_module(self.urlconf_name)
  File "c:\Python27\lib\importlib\__init__.py", line 37, in import_module
    __import__(name)
  File "c:\Users\Junior\tappsi_test\tappsi_test\urls.py", line 2, in <module>
    from tappsi_api.views import UserViewSet, RideViewSet, AvailableView
  File "c:\Users\Junior\tappsi_test\tappsi_api\views.py", line 77
    users=User.objects.filter(user=user_id,, many=True)
                                           ^
SyntaxError: invalid syntax
ERROR:django.request:Internal Server Error: /api/v1/users/
Traceback (most recent call last):
  File "c:\Python27\lib\site-packages\django\core\handlers\base.py", line 98, in get_response
    resolver_match = resolver.resolve(request.path_info)
  File "c:\Python27\lib\site-packages\django\core\urlresolvers.py", line 338, in resolve
    for pattern in self.url_patterns:
  File "c:\Python27\lib\site-packages\django\core\urlresolvers.py", line 367, in url_patterns
    patterns = getattr(self.urlconf_module, "urlpatterns", self.urlconf_module)
  File "c:\Python27\lib\site-packages\django\core\urlresolvers.py", line 361, in urlconf_module
    self._urlconf_module = import_module(self.urlconf_name)
  File "c:\Python27\lib\importlib\__init__.py", line 37, in import_module
    __import__(name)
  File "c:\Users\Junior\tappsi_test\tappsi_test\urls.py", line 2, in <module>
    from tappsi_api.views import UserViewSet, RideViewSet, AvailableView
  File "c:\Users\Junior\tappsi_test\tappsi_api\views.py", line 3, in <module>
    from tappsi_api.models import Profile, Ride
ImportError: cannot import name Profile
ERROR:django.request:Internal Server Error: /api/v1/users/
Traceback (most recent call last):
  File "c:\Python27\lib\site-packages\django\core\handlers\base.py", line 98, in get_response
    resolver_match = resolver.resolve(request.path_info)
  File "c:\Python27\lib\site-packages\django\core\urlresolvers.py", line 338, in resolve
    for pattern in self.url_patterns:
  File "c:\Python27\lib\site-packages\django\core\urlresolvers.py", line 367, in url_patterns
    patterns = getattr(self.urlconf_module, "urlpatterns", self.urlconf_module)
  File "c:\Python27\lib\site-packages\django\core\urlresolvers.py", line 361, in urlconf_module
    self._urlconf_module = import_module(self.urlconf_name)
  File "c:\Python27\lib\importlib\__init__.py", line 37, in import_module
    __import__(name)
  File "c:\Users\Junior\tappsi_test\tappsi_test\urls.py", line 2, in <module>
    from tappsi_api.views import UserViewSet, RideViewSet, AvailableView
  File "c:\Users\Junior\tappsi_test\tappsi_api\views.py", line 4, in <module>
    from tappsi_api.serializers import UserSerializer, RideSerializer, DriverSerializer
  File "c:\Users\Junior\tappsi_test\tappsi_api\serializers.py", line 7, in <module>
    class ProfileSerializer(serializers.ModelSerializer):
  File "c:\Users\Junior\tappsi_test\tappsi_api\serializers.py", line 8, in ProfileSerializer
    class Meta:
  File "c:\Users\Junior\tappsi_test\tappsi_api\serializers.py", line 9, in Meta
    model = Profile
NameError: name 'Profile' is not defined
ERROR:django.request:Internal Server Error: /api/v1/users/
Traceback (most recent call last):
  File "c:\Python27\lib\site-packages\django\core\handlers\base.py", line 137, in get_response
    response = response.render()
  File "c:\Python27\lib\site-packages\django\template\response.py", line 103, in render
    self.content = self.rendered_content
  File "c:\Python27\lib\site-packages\rest_framework\response.py", line 59, in rendered_content
    ret = renderer.render(self.data, media_type, context)
  File "c:\Python27\lib\site-packages\rest_framework\renderers.py", line 99, in render
    separators=separators
  File "c:\Python27\lib\json\__init__.py", line 250, in dumps
    sort_keys=sort_keys, **kw).encode(obj)
  File "c:\Python27\lib\json\encoder.py", line 207, in encode
    chunks = self.iterencode(o, _one_shot=True)
  File "c:\Python27\lib\json\encoder.py", line 270, in iterencode
    return _iterencode(o, 0)
  File "c:\Python27\lib\site-packages\rest_framework\utils\encoders.py", line 61, in default
    return super(JSONEncoder, self).default(obj)
  File "c:\Python27\lib\json\encoder.py", line 184, in default
    raise TypeError(repr(o) + " is not JSON serializable")
TypeError: OperationalError('no such table: tappsi_api_userprofile',) is not JSON serializable
ERROR:django.request:Internal Server Error: /api/v1/users/
Traceback (most recent call last):
  File "c:\Python27\lib\site-packages\django\core\handlers\base.py", line 137, in get_response
    response = response.render()
  File "c:\Python27\lib\site-packages\django\template\response.py", line 103, in render
    self.content = self.rendered_content
  File "c:\Python27\lib\site-packages\rest_framework\response.py", line 59, in rendered_content
    ret = renderer.render(self.data, media_type, context)
  File "c:\Python27\lib\site-packages\rest_framework\renderers.py", line 99, in render
    separators=separators
  File "c:\Python27\lib\json\__init__.py", line 250, in dumps
    sort_keys=sort_keys, **kw).encode(obj)
  File "c:\Python27\lib\json\encoder.py", line 207, in encode
    chunks = self.iterencode(o, _one_shot=True)
  File "c:\Python27\lib\json\encoder.py", line 270, in iterencode
    return _iterencode(o, 0)
  File "c:\Python27\lib\site-packages\rest_framework\utils\encoders.py", line 61, in default
    return super(JSONEncoder, self).default(obj)
  File "c:\Python27\lib\json\encoder.py", line 184, in default
    raise TypeError(repr(o) + " is not JSON serializable")
TypeError: OperationalError('no such table: tappsi_api_userprofile',) is not JSON serializable
ERROR:django.request:Internal Server Error: /api/v1/users/
Traceback (most recent call last):
  File "c:\Python27\lib\site-packages\django\core\handlers\base.py", line 137, in get_response
    response = response.render()
  File "c:\Python27\lib\site-packages\django\template\response.py", line 103, in render
    self.content = self.rendered_content
  File "c:\Python27\lib\site-packages\rest_framework\response.py", line 59, in rendered_content
    ret = renderer.render(self.data, media_type, context)
  File "c:\Python27\lib\site-packages\rest_framework\renderers.py", line 99, in render
    separators=separators
  File "c:\Python27\lib\json\__init__.py", line 250, in dumps
    sort_keys=sort_keys, **kw).encode(obj)
  File "c:\Python27\lib\json\encoder.py", line 207, in encode
    chunks = self.iterencode(o, _one_shot=True)
  File "c:\Python27\lib\json\encoder.py", line 270, in iterencode
    return _iterencode(o, 0)
  File "c:\Python27\lib\site-packages\rest_framework\utils\encoders.py", line 61, in default
    return super(JSONEncoder, self).default(obj)
  File "c:\Python27\lib\json\encoder.py", line 184, in default
    raise TypeError(repr(o) + " is not JSON serializable")
TypeError: AssertionError(u'`create()` did not return an object instance.',) is not JSON serializable
ERROR:django.request:Internal Server Error: /api/v1/users/
Traceback (most recent call last):
  File "c:\Python27\lib\site-packages\django\core\handlers\base.py", line 137, in get_response
    response = response.render()
  File "c:\Python27\lib\site-packages\django\template\response.py", line 103, in render
    self.content = self.rendered_content
  File "c:\Python27\lib\site-packages\rest_framework\response.py", line 59, in rendered_content
    ret = renderer.render(self.data, media_type, context)
  File "c:\Python27\lib\site-packages\rest_framework\renderers.py", line 99, in render
    separators=separators
  File "c:\Python27\lib\json\__init__.py", line 250, in dumps
    sort_keys=sort_keys, **kw).encode(obj)
  File "c:\Python27\lib\json\encoder.py", line 207, in encode
    chunks = self.iterencode(o, _one_shot=True)
  File "c:\Python27\lib\json\encoder.py", line 270, in iterencode
    return _iterencode(o, 0)
  File "c:\Python27\lib\site-packages\rest_framework\utils\encoders.py", line 61, in default
    return super(JSONEncoder, self).default(obj)
  File "c:\Python27\lib\json\encoder.py", line 184, in default
    raise TypeError(repr(o) + " is not JSON serializable")
TypeError: KeyError('phone',) is not JSON serializable
ERROR:django.request:Internal Server Error: /api/v1/users/
Traceback (most recent call last):
  File "c:\Python27\lib\site-packages\django\core\handlers\base.py", line 98, in get_response
    resolver_match = resolver.resolve(request.path_info)
  File "c:\Python27\lib\site-packages\django\core\urlresolvers.py", line 338, in resolve
    for pattern in self.url_patterns:
  File "c:\Python27\lib\site-packages\django\core\urlresolvers.py", line 367, in url_patterns
    patterns = getattr(self.urlconf_module, "urlpatterns", self.urlconf_module)
  File "c:\Python27\lib\site-packages\django\core\urlresolvers.py", line 361, in urlconf_module
    self._urlconf_module = import_module(self.urlconf_name)
  File "c:\Python27\lib\importlib\__init__.py", line 37, in import_module
    __import__(name)
  File "c:\Users\Junior\tappsi_test\tappsi_test\urls.py", line 11, in <module>
    from tappsi_api.views import UserViewSet, RideViewSet, AvailableView
  File "c:\Users\Junior\tappsi_test\tappsi_api\views.py", line 11, in <module>
    from tappsi_api.models import Profile, Ride, Drive
ImportError: cannot import name Drive
INFO:root:R: {u'origin': u'Cruz del perdon', u'active': 1, u'taxi_drive_id': 8, u'client_id': 12, u'destiny': u'Casco central'} 
ERROR:django.request:Internal Server Error: /api/v1/users/
Traceback (most recent call last):
  File "c:\Python27\lib\site-packages\django\core\handlers\base.py", line 98, in get_response
    resolver_match = resolver.resolve(request.path_info)
  File "c:\Python27\lib\site-packages\django\core\urlresolvers.py", line 338, in resolve
    for pattern in self.url_patterns:
  File "c:\Python27\lib\site-packages\django\core\urlresolvers.py", line 367, in url_patterns
    patterns = getattr(self.urlconf_module, "urlpatterns", self.urlconf_module)
  File "c:\Python27\lib\site-packages\django\core\urlresolvers.py", line 361, in urlconf_module
    self._urlconf_module = import_module(self.urlconf_name)
  File "c:\Python27\lib\importlib\__init__.py", line 37, in import_module
    __import__(name)
  File "c:\Users\Junior\tappsi_test\tappsi_test\urls.py", line 11, in <module>
    from tappsi_api.views import UserViewSet, RideViewSet, AvailableView
  File "c:\Users\Junior\tappsi_test\tappsi_api\views.py", line 11, in <module>
    from tappsi_api.models import Profile, Ride, Drive
ImportError: cannot import name Drive
INFO:root:R: {u'origin': u'Cruz del perdon', u'active': 1, u'taxi_drive_id': 8, u'client_id': 12, u'destiny': u'Casco central'} 
INFO:root:R: {u'origin': u'Cruz del perdon', u'active': 1, u'taxi_drive_id': 8, u'client_id': 12, u'destiny': u'Casco central'} 
INFO:root:R: {u'origin': u'Cruz del perdon', u'active': 1, u'taxi_driver_id': 8, u'client_id': 12, u'destiny': u'Casco central'} 
INFO:root:R: {u'origin': u'Centro, carrera 12', u'active': 0, u'taxi_driver_id': 3, u'client_id': 10, u'destiny': u'La salida de calabozo'} 
INFO:root:R: {u'origin': u'La hoyada, torre 5', u'active': 1, u'taxi_driver_id': 15, u'client_id': 9, u'destiny': u'La california'} 
INFO:root:R: {u'origin': u'Miranda, parque central', u'active': 0, u'taxi_driver_id': 7, u'client_id': 2, u'destiny': u'Hosp. El llanito'} 
INFO:root:R: {u'origin': u'Los samanes', u'active': 0, u'taxi_driver_id': 4, u'client_id': 11, u'destiny': u'Chaparral'} 
INFO:root:R: {u'origin': u'Cruz del perdon', u'active': 1, u'taxi_driver_id': 8, u'client_id': 12, u'destiny': u'Casco central'} 
INFO:root:R: {u'origin': u'Centro, carrera 12', u'active': 0, u'taxi_driver_id': 3, u'client_id': 10, u'destiny': u'La salida de calabozo'} 
INFO:root:R: {u'origin': u'La hoyada, torre 5', u'active': 1, u'taxi_driver_id': 15, u'client_id': 9, u'destiny': u'La california'} 
INFO:root:R: {u'origin': u'Miranda, parque central', u'active': 0, u'taxi_driver_id': 7, u'client_id': 2, u'destiny': u'Hosp. El llanito'} 
INFO:root:R: {u'origin': u'Los samanes', u'active': 0, u'taxi_driver_id': 4, u'client_id': 11, u'destiny': u'Chaparral'} 
